<?xml version="1.0" encoding="utf-8"?>
<!-- This URDF was automatically created by SolidWorks to URDF Exporter! Originally created by Stephen Brawner (brawner@gmail.com) 
     Commit Version: 1.6.0-4-g7f85cfe  Build Version: 1.6.7995.38578
     For more information, please see http://wiki.ros.org/sw_urdf_exporter -->
<robot
  name="birdbot03">
  <link
    name="base_link">
    <inertial>
      <origin
        xyz="-0.0083163 0.032078 -8.7473E-05"
        rpy="0 0 0" />
      <mass
        value="0.24692" />
      <inertia
        ixx="0.00022169"
        ixy="-0.00024993"
        ixz="-1.2954E-07"
        iyy="0.00062849"
        iyz="7.1402E-08"
        izz="0.00076587" />
    </inertial>
    <visual>
      <origin
        xyz="0 0 0"
        rpy="0 0 0" />
      <geometry>
        <mesh
          filename="package://urdf_vis/meshes/birdbot_v00/base_link.STL" />
      </geometry>
      <material
        name="">
        <color
          rgba="0.79216 0.81961 0.93333 1" />
      </material>
    </visual>
    <collision>
      <origin
        xyz="0 0 0"
        rpy="0 0 0" />
      <geometry>
        <mesh
          filename="package://urdf_vis/meshes/birdbot_v00/base_link.STL" />
      </geometry>
    </collision>
  </link>
  <link
    name="left_pelvis_link">
    <inertial>
      <origin
        xyz="0.019519 0.035904 0.021983"
        rpy="0 0 0" />
      <mass
        value="0.02404" />
      <inertia
        ixx="1.1308E-05"
        ixy="-1.9409E-08"
        ixz="-2.7593E-09"
        iyy="5.7887E-06"
        iyz="-3.5405E-06"
        izz="9.5993E-06" />
    </inertial>
    <visual>
      <origin
        xyz="0 0 0"
        rpy="0 0 0" />
      <geometry>
        <mesh
          filename="package://urdf_vis/meshes/birdbot_v00/left_pelvis_link.STL" />
      </geometry>
      <material
        name="">
        <color
          rgba="0.79216 0.81961 0.93333 1" />
      </material>
    </visual>
    <collision>
      <origin
        xyz="0 0 0"
        rpy="0 0 0" />
      <geometry>
        <mesh
          filename="package://urdf_vis/meshes/birdbot_v00/left_pelvis_link.STL" />
      </geometry>
    </collision>
  </link>
  <joint
    name="left_pelvis_joint"
    type="continuous">
    <origin
      xyz="0 -0.0248 0"
      rpy="-2.618 0 -1.5708" />
    <parent
      link="base_link" />
    <child
      link="left_pelvis_link" />
    <axis
      xyz="1 0 0" />
  </joint>
  <link
    name="left_femur_link">
    <inertial>
      <origin
        xyz="-0.072099 -0.00086515 -0.01149"
        rpy="0 0 0" />
      <mass
        value="0.032722" />
      <inertia
        ixx="3.0841E-06"
        ixy="1.0743E-07"
        ixz="-1.0948E-07"
        iyy="4.6097E-05"
        iyz="-1.7563E-10"
        izz="4.7031E-05" />
    </inertial>
    <visual>
      <origin
        xyz="0 0 0"
        rpy="0 0 0" />
      <geometry>
        <mesh
          filename="package://urdf_vis/meshes/birdbot_v00/left_femur_link.STL" />
      </geometry>
      <material
        name="">
        <color
          rgba="0.79216 0.81961 0.93333 1" />
      </material>
    </visual>
    <collision>
      <origin
        xyz="0 0 0"
        rpy="0 0 0" />
      <geometry>
        <mesh
          filename="package://urdf_vis/meshes/birdbot_v00/left_femur_link.STL" />
      </geometry>
    </collision>
  </link>
  <joint
    name="left_femur_joint"
    type="continuous">
    <origin
      xyz="0.0089 0.073612 0.0425"
      rpy="-1.5708 1.3727 1.5708" />
    <parent
      link="left_pelvis_link" />
    <child
      link="left_femur_link" />
    <axis
      xyz="0 0 1" />
  </joint>
  <link
    name="left_tibia_link">
    <inertial>
      <origin
        xyz="0.010726 0.0041086 0.037407"
        rpy="0 0 0" />
      <mass
        value="0.017901" />
      <inertia
        ixx="2.5332E-05"
        ixy="-1.7982E-09"
        ixz="-2.9013E-09"
        iyy="2.6017E-05"
        iyz="-4.0543E-06"
        izz="3.0759E-06" />
    </inertial>
    <visual>
      <origin
        xyz="0 0 0"
        rpy="0 0 0" />
      <geometry>
        <mesh
          filename="package://urdf_vis/meshes/birdbot_v00/left_tibia_link.STL" />
      </geometry>
      <material
        name="">
        <color
          rgba="0.79216 0.81961 0.93333 1" />
      </material>
    </visual>
    <collision>
      <origin
        xyz="0 0 0"
        rpy="0 0 0" />
      <geometry>
        <mesh
          filename="package://urdf_vis/meshes/birdbot_v00/left_tibia_link.STL" />
      </geometry>
    </collision>
  </link>
  <joint
    name="left_tibia_joint"
    type="continuous">
    <origin
      xyz="-0.11 -0.00030113 0"
      rpy="2.4863 1.5708 0" />
    <parent
      link="left_femur_link" />
    <child
      link="left_tibia_link" />
    <axis
      xyz="1 0 0" />
  </joint>
  <link
    name="left_foot_link">
    <inertial>
      <origin
        xyz="0.017051 0.012553 0.011917"
        rpy="0 0 0" />
      <mass
        value="0.010112" />
      <inertia
        ixx="7.0777E-07"
        ixy="-6.0699E-08"
        ixz="8.5793E-09"
        iyy="1.104E-06"
        iyz="-5.4335E-09"
        izz="8.9327E-07" />
    </inertial>
    <visual>
      <origin
        xyz="0 0 0"
        rpy="0 0 0" />
      <geometry>
        <mesh
          filename="package://urdf_vis/meshes/birdbot_v00/left_foot_link.STL" />
      </geometry>
      <material
        name="">
        <color
          rgba="0.79216 0.81961 0.93333 1" />
      </material>
    </visual>
    <collision>
      <origin
        xyz="0 0 0"
        rpy="0 0 0" />
      <geometry>
        <mesh
          filename="package://urdf_vis/meshes/birdbot_v00/left_foot_link.STL" />
      </geometry>
    </collision>
  </link>
  <joint
    name="left_foot_joint"
    type="continuous">
    <origin
      xyz="0 0.013912 0.10407"
      rpy="1.5708 0.066441 1.5708" />
    <parent
      link="left_tibia_link" />
    <child
      link="left_foot_link" />
    <axis
      xyz="0 0 1" />
  </joint>
  <link
    name="right_pelvis_link">
    <inertial>
      <origin
        xyz="0 0 0"
        rpy="0 0 0" />
      <mass
        value="0" />
      <inertia
        ixx="0"
        ixy="0"
        ixz="0"
        iyy="0"
        iyz="0"
        izz="0" />
    </inertial>
    <visual>
      <origin
        xyz="0 0 0"
        rpy="0 0 0" />
      <geometry>
        <mesh
          filename="package://urdf_vis/meshes/birdbot_v00/right_pelvis_link.STL" />
      </geometry>
      <material
        name="">
        <color
          rgba="1 1 1 1" />
      </material>
    </visual>
    <collision>
      <origin
        xyz="0 0 0"
        rpy="0 0 0" />
      <geometry>
        <mesh
          filename="package://urdf_vis/meshes/birdbot_v00/right_pelvis_link.STL" />
      </geometry>
    </collision>
  </link>
  <joint
    name="right_pelvis_joint"
    type="continuous">
    <origin
      xyz="0 0.029412 0"
      rpy="-2.618 0 -1.5708" />
    <parent
      link="base_link" />
    <child
      link="right_pelvis_link" />
    <axis
      xyz="1 0 0" />
  </joint>
  <link
    name="right_femur_link">
    <inertial>
      <origin
        xyz="-0.0720989773487731 -0.000865147944021635 0.0111103166480375"
        rpy="0 0 0" />
      <mass
        value="0.0327221041849724" />
      <inertia
        ixx="3.0840702954567E-06"
        ixy="1.07434599059443E-07"
        ixz="-1.09478416501742E-07"
        iyy="4.60974993622538E-05"
        iyz="-1.75626637902618E-10"
        izz="4.70309291598694E-05" />
    </inertial>
    <visual>
      <origin
        xyz="0 0 0"
        rpy="0 0 0" />
      <geometry>
        <mesh
          filename="package://urdf_vis/meshes/birdbot_v00/right_femur_link.STL" />
      </geometry>
      <material
        name="">
        <color
          rgba="0.792156862745098 0.819607843137255 0.933333333333333 1" />
      </material>
    </visual>
    <collision>
      <origin
        xyz="0 0 0"
        rpy="0 0 0" />
      <geometry>
        <mesh
          filename="package://urdf_vis/meshes/birdbot_v00/right_femur_link.STL" />
      </geometry>
    </collision>
  </link>
  <joint
    name="right_femur_joint"
    type="continuous">
    <origin
      xyz="-0.0042882 0.073612 0.0425"
      rpy="-1.5708 1.3727 1.5708" />
    <parent
      link="right_pelvis_link" />
    <child
      link="right_femur_link" />
    <axis
      xyz="0 0 1" />
  </joint>
  <link
    name="right_tibia_link">
    <inertial>
      <origin
        xyz="-0.0142736692913956 0.00410860361893558 0.0374072084379573"
        rpy="0 0 0" />
      <mass
        value="0.0179012926659031" />
      <inertia
        ixx="2.53318356380153E-05"
        ixy="-1.79813333927047E-09"
        ixz="-2.9009953715204E-09"
        iyy="2.60169931743458E-05"
        iyz="-4.05425198775302E-06"
        izz="3.07586379174121E-06" />
    </inertial>
    <visual>
      <origin
        xyz="0 0 0"
        rpy="0 0 0" />
      <geometry>
        <mesh
          filename="package://urdf_vis/meshes/birdbot_v00/right_tibia_link.STL" />
      </geometry>
      <material
        name="">
        <color
          rgba="0.792156862745098 0.819607843137255 0.933333333333333 1" />
      </material>
    </visual>
    <collision>
      <origin
        xyz="0 0 0"
        rpy="0 0 0" />
      <geometry>
        <mesh
          filename="package://urdf_vis/meshes/birdbot_v00/right_tibia_link.STL" />
      </geometry>
    </collision>
  </link>
  <joint
    name="right_tibia_joint"
    type="continuous">
    <origin
      xyz="-0.11 -0.00030113 0"
      rpy="2.4863 1.5708 0" />
    <parent
      link="right_femur_link" />
    <child
      link="right_tibia_link" />
    <axis
      xyz="1 0 0" />
  </joint>
  <link
    name="right_foot_link">
    <inertial>
      <origin
        xyz="0.0170509864208514 0.0125530967536815 -0.0128828869801942"
        rpy="0 0 0" />
      <mass
        value="0.0101123787795885" />
      <inertia
        ixx="7.07770937188851E-07"
        ixy="-6.0698536848485E-08"
        ixz="8.57926142576752E-09"
        iyy="1.10398348074849E-06"
        iyz="-5.43347079034745E-09"
        izz="8.93271095817075E-07" />
    </inertial>
    <visual>
      <origin
        xyz="0 0 0"
        rpy="0 0 0" />
      <geometry>
        <mesh
          filename="package://urdf_vis/meshes/birdbot_v00/right_foot_link.STL" />
      </geometry>
      <material
        name="">
        <color
          rgba="0.792156862745098 0.819607843137255 0.933333333333333 1" />
      </material>
    </visual>
    <collision>
      <origin
        xyz="0 0 0"
        rpy="0 0 0" />
      <geometry>
        <mesh
          filename="package://urdf_vis/meshes/birdbot_v00/right_foot_link.STL" />
      </geometry>
    </collision>
  </link>
  <joint
    name="right_foot_joint"
    type="continuous">
    <origin
      xyz="-0.00019997 0.013912 0.10407"
      rpy="1.5708 0.066441 1.5708" />
    <parent
      link="right_tibia_link" />
    <child
      link="right_foot_link" />
    <axis
      xyz="0 0 1" />
  </joint>
</robot>