<?xml version="1.0" encoding="utf-8"?>
<!-- This URDF was automatically created by SolidWorks to URDF Exporter! Originally created by Stephen Brawner (brawner@gmail.com) 
     Commit Version: 1.6.0-4-g7f85cfe  Build Version: 1.6.7995.38578
     For more information, please see http://wiki.ros.org/sw_urdf_exporter -->
<robot
  name="birdbot_v01">
  <link
    name="base_link">
    <inertial>
      <origin
        xyz="0.00953226749992518 -8.74725977887722E-05 0.0329563309440079"
        rpy="0 0 0" />
      <mass
        value="0.246924141249937" />
      <inertia
        ixx="0.000221694453566261"
        ixy="1.29544470448472E-07"
        ixz="0.000249933379178087"
        iyy="0.000765868788750837"
        iyz="7.14022846072767E-08"
        izz="0.000628489505207198" />
    </inertial>
    <visual>
      <origin
        xyz="0 0 0"
        rpy="0 0 0" />
      <geometry>
        <mesh
          filename="package://urdf_vis/meshes/birdbot/base_link.STL" />
      </geometry>
      <material
        name="">
        <color
          rgba="0.792156862745098 0.819607843137255 0.933333333333333 1" />
      </material>
    </visual>
    <collision>
      <origin
        xyz="0 0 0"
        rpy="0 0 0" />
      <geometry>
        <mesh
          filename="package://urdf_vis/meshes/birdbot/base_link.STL" />
      </geometry>
    </collision>
  </link>
  <link
    name="left_pelvis_link">
    <inertial>
      <origin
        xyz="0.0195191765439385 -0.00108555214162335 0.0420855750240419"
        rpy="0 0 0" />
      <mass
        value="0.0240397099024521" />
      <inertia
        ixx="1.13077853390725E-05"
        ixy="-7.31468831589693E-09"
        ixz="-1.81875737043039E-08"
        iyy="1.1712758026971E-05"
        iyz="1.20218585480779E-07"
        izz="3.67522461116956E-06" />
    </inertial>
    <visual>
      <origin
        xyz="0 0 0"
        rpy="0 0 0" />
      <geometry>
        <mesh
          filename="package://urdf_vis/meshes/birdbot/left_pelvis_link.STL" />
      </geometry>
      <material
        name="">
        <color
          rgba="0.792156862745098 0.819607843137255 0.933333333333333 1" />
      </material>
    </visual>
    <collision>
      <origin
        xyz="0 0 0"
        rpy="0 0 0" />
      <geometry>
        <mesh
          filename="package://urdf_vis/meshes/birdbot/left_pelvis_link.STL" />
      </geometry>
    </collision>
  </link>
  <joint
    name="left_pelvis_joint"
    type="continuous">
    <origin
      xyz="0.00121592635923147 -0.000878363870458104 0.0247999999999999"
      rpy="1.64268091463056 -1.5707963267949 0" />
    <parent
      link="base_link" />
    <child
      link="left_pelvis_link" />
    <axis
      xyz="1 0 0" />
  </joint>
  <link
    name="left_femur_link">
    <inertial>
      <origin
        xyz="-0.0720989770041662 -0.000865147911771433 -0.0114896832158845"
        rpy="0 0 0" />
      <mass
        value="0.0327221036602836" />
      <inertia
        ixx="3.08407026620197E-06"
        ixy="1.07434484253467E-07"
        ixz="-1.09478320149193E-07"
        iyy="4.60974980639339E-05"
        iyz="-1.75643192247145E-10"
        izz="4.70309278366279E-05" />
    </inertial>
    <visual>
      <origin
        xyz="0 0 0"
        rpy="0 0 0" />
      <geometry>
        <mesh
          filename="package://urdf_vis/meshes/birdbot/left_femur_link.STL" />
      </geometry>
      <material
        name="">
        <color
          rgba="0.792156862745098 0.819607843137255 0.933333333333333 1" />
      </material>
    </visual>
    <collision>
      <origin
        xyz="0 0 0"
        rpy="0 0 0" />
      <geometry>
        <mesh
          filename="package://urdf_vis/meshes/birdbot/left_femur_link.STL" />
      </geometry>
    </collision>
  </link>
  <joint
    name="left_femur_joint"
    type="continuous">
    <origin
      xyz="0.00890000000000016 0 0.0850000000000003"
      rpy="-1.5707963267949 0.551803682745526 1.5707963267949" />
    <parent
      link="left_pelvis_link" />
    <child
      link="left_femur_link" />
    <axis
      xyz="0 0 1" />
  </joint>
  <link
    name="left_tibia_link">
    <inertial>
      <origin
        xyz="0.0107263256836939 -0.000883743601458931 0.0376217899198245"
        rpy="0 0 0" />
      <mass
        value="0.0179012857998287" />
      <inertia
        ixx="2.53318343152091E-05"
        ixy="-1.39910232320532E-09"
        ixz="-3.11428063486745E-09"
        iyy="2.66791207407098E-05"
        iyz="-8.99208225651885E-07"
        izz="2.41373390652192E-06" />
    </inertial>
    <visual>
      <origin
        xyz="0 0 0"
        rpy="0 0 0" />
      <geometry>
        <mesh
          filename="package://urdf_vis/meshes/birdbot/left_tibia_link.STL" />
      </geometry>
      <material
        name="">
        <color
          rgba="0.792156862745098 0.819607843137255 0.933333333333333 1" />
      </material>
    </visual>
    <collision>
      <origin
        xyz="0 0 0"
        rpy="0 0 0" />
      <geometry>
        <mesh
          filename="package://urdf_vis/meshes/birdbot/left_tibia_link.STL" />
      </geometry>
    </collision>
  </link>
  <joint
    name="left_tibia_joint"
    type="continuous">
    <origin
      xyz="-0.109999587813108 -0.000301132771852453 0"
      rpy="1.5202434435008 1.5707963267949 0" />
    <parent
      link="left_femur_link" />
    <child
      link="left_tibia_link" />
    <axis
      xyz="1 0 0" />
  </joint>
  <link
    name="left_foot_link">
    <inertial>
      <origin
        xyz="0.0170509852161169 0.0125530964960417 0.011917138427946"
        rpy="0 0 0" />
      <mass
        value="0.0101123797998784" />
      <inertia
        ixx="7.0777096383425E-07"
        ixy="-6.06985357181719E-08"
        ixz="8.57926912423409E-09"
        iyy="1.10398350725594E-06"
        iyz="-5.4334764771971E-09"
        izz="8.9327110210762E-07" />
    </inertial>
    <visual>
      <origin
        xyz="0 0 0"
        rpy="0 0 0" />
      <geometry>
        <mesh
          filename="package://urdf_vis/meshes/birdbot/left_foot_link.STL" />
      </geometry>
      <material
        name="">
        <color
          rgba="0.792156862745098 0.819607843137255 0.933333333333333 1" />
      </material>
    </visual>
    <collision>
      <origin
        xyz="0 0 0"
        rpy="0 0 0" />
      <geometry>
        <mesh
          filename="package://urdf_vis/meshes/birdbot/left_foot_link.STL" />
      </geometry>
    </collision>
  </link>
  <joint
    name="left_foot_joint"
    type="continuous">
    <origin
      xyz="0 0 0.105"
      rpy="1.5707963267949 -0.530471978203955 1.5707963267949" />
    <parent
      link="left_tibia_link" />
    <child
      link="left_foot_link" />
    <axis
      xyz="0 0 1" />
  </joint>
  <link
    name="right_pelvis_link">
    <inertial>
      <origin
        xyz="-0.0205308234392045 -0.00108555211230882 0.0420855749701808"
        rpy="0 0 0" />
      <mass
        value="0.0240397097940218" />
      <inertia
        ixx="1.13077853153155E-05"
        ixy="-7.31468153039908E-09"
        ixz="-1.81875762280757E-08"
        iyy="1.17127580008201E-05"
        iyz="1.20218578982657E-07"
        izz="3.67522459932004E-06" />
    </inertial>
    <visual>
      <origin
        xyz="0 0 0"
        rpy="0 0 0" />
      <geometry>
        <mesh
          filename="package://urdf_vis/meshes/birdbot/right_pelvis_link.STL" />
      </geometry>
      <material
        name="">
        <color
          rgba="0.792156862745098 0.819607843137255 0.933333333333333 1" />
      </material>
    </visual>
    <collision>
      <origin
        xyz="0 0 0"
        rpy="0 0 0" />
      <geometry>
        <mesh
          filename="package://urdf_vis/meshes/birdbot/right_pelvis_link.STL" />
      </geometry>
    </collision>
  </link>
  <joint
    name="right_pelvis_joint"
    type="continuous">
    <origin
      xyz="0.00121592635923147 -0.000878363870458081 -0.0252000000000001"
      rpy="1.64268091463056 -1.5707963267949 0" />
    <parent
      link="base_link" />
    <child
      link="right_pelvis_link" />
    <axis
      xyz="1 0 0" />
  </joint>
  <link
    name="right_femur_link">
    <inertial>
      <origin
        xyz="-0.0720989776555793 -0.000865147977103992 0.0285603166977322"
        rpy="0 0 0" />
      <mass
        value="0.0327221032031459" />
      <inertia
        ixx="3.08407024028201E-06"
        ixy="1.07434542594445E-07"
        ixz="-1.09478236113346E-07"
        iyy="4.609749765575E-05"
        iyz="-1.75630614982521E-10"
        izz="4.70309274374976E-05" />
    </inertial>
    <visual>
      <origin
        xyz="0 0 0"
        rpy="0 0 0" />
      <geometry>
        <mesh
          filename="package://urdf_vis/meshes/birdbot/right_femur_link.STL" />
      </geometry>
      <material
        name="">
        <color
          rgba="0.792156862745098 0.819607843137255 0.933333333333333 1" />
      </material>
    </visual>
    <collision>
      <origin
        xyz="0 0 0"
        rpy="0 0 0" />
      <geometry>
        <mesh
          filename="package://urdf_vis/meshes/birdbot/right_femur_link.STL" />
      </geometry>
    </collision>
  </link>
  <joint
    name="right_femur_joint"
    type="continuous">
    <origin
      xyz="0.00890000000000016 0 0.0850000000000003"
      rpy="-1.5707963267949 0.551803682745524 1.5707963267949" />
    <parent
      link="right_pelvis_link" />
    <child
      link="right_femur_link" />
    <axis
      xyz="0 0 1" />
  </joint>
  <link
    name="right_tibia_link">
    <inertial>
      <origin
        xyz="-0.0293236743163062 -0.000883743601458958 0.0376217899198242"
        rpy="0 0 0" />
      <mass
        value="0.0179012857998287" />
      <inertia
        ixx="2.53318343152092E-05"
        ixy="-1.39910232320592E-09"
        ixz="-3.11428063486968E-09"
        iyy="2.66791207407098E-05"
        iyz="-8.99208225651905E-07"
        izz="2.41373390652193E-06" />
    </inertial>
    <visual>
      <origin
        xyz="0 0 0"
        rpy="0 0 0" />
      <geometry>
        <mesh
          filename="package://urdf_vis/meshes/birdbot/right_tibia_link.STL" />
      </geometry>
      <material
        name="">
        <color
          rgba="0.792156862745098 0.819607843137255 0.933333333333333 1" />
      </material>
    </visual>
    <collision>
      <origin
        xyz="0 0 0"
        rpy="0 0 0" />
      <geometry>
        <mesh
          filename="package://urdf_vis/meshes/birdbot/right_tibia_link.STL" />
      </geometry>
    </collision>
  </link>
  <joint
    name="right_tibia_joint"
    type="continuous">
    <origin
      xyz="-0.109999587813108 -0.000301132771852522 0"
      rpy="1.5202434435008 1.5707963267949 0" />
    <parent
      link="right_femur_link" />
    <child
      link="right_tibia_link" />
    <axis
      xyz="1 0 0" />
  </joint>
  <link
    name="right_foot_link">
    <inertial>
      <origin
        xyz="0.017050985216117 0.00255309649604168 -0.078132861572054"
        rpy="0 0 0" />
      <mass
        value="0.0101123797998784" />
      <inertia
        ixx="7.07770963834249E-07"
        ixy="-6.06985357181728E-08"
        ixz="8.5792691242335E-09"
        iyy="1.10398350725593E-06"
        iyz="-5.43347647719802E-09"
        izz="8.93271102107618E-07" />
    </inertial>
    <visual>
      <origin
        xyz="0 0 0"
        rpy="0 0 0" />
      <geometry>
        <mesh
          filename="package://urdf_vis/meshes/birdbot/right_foot_link.STL" />
      </geometry>
      <material
        name="">
        <color
          rgba="0.792156862745098 0.819607843137255 0.933333333333333 1" />
      </material>
    </visual>
    <collision>
      <origin
        xyz="0 0 0"
        rpy="0 0 0" />
      <geometry>
        <mesh
          filename="package://urdf_vis/meshes/birdbot/right_foot_link.STL" />
      </geometry>
    </collision>
  </link>
  <joint
    name="right_foot_joint"
    type="continuous">
    <origin
      xyz="0.05 -0.00505940511014047 0.113625683737043"
      rpy="1.5707963267949 -0.530471978203955 1.5707963267949" />
    <parent
      link="right_tibia_link" />
    <child
      link="right_foot_link" />
    <axis
      xyz="0 0 1" />
  </joint>
</robot>