<?xml version="1.0" encoding="utf-8"?>
<!-- This URDF was automatically created by SolidWorks to URDF Exporter! Originally created by Stephen Brawner (brawner@gmail.com) 
     Commit Version: 1.6.0-4-g7f85cfe  Build Version: 1.6.7995.38578
     For more information, please see http://wiki.ros.org/sw_urdf_exporter -->
<robot
  name="birdbot02">
  <link
    name="base_link">
    <inertial>
      <origin
        xyz="-0.024887 -0.0045681 -0.032822"
        rpy="0 0 0" />
      <mass
        value="0.24692" />
      <inertia
        ixx="0.00076587"
        ixy="9.2445E-08"
        ixz="-1.1547E-07"
        iyy="0.00010459"
        iyz="-3.3381E-05"
        izz="0.0007456" />
    </inertial>
    <visual>
      <origin
        xyz="0 0 0"
        rpy="0 0 0" />
      <geometry>
        <mesh
          filename="package://birdbot02/meshes/base_link.STL" />
      </geometry>
      <material
        name="">
        <color
          rgba="0.79216 0.81961 0.93333 1" />
      </material>
    </visual>
    <collision>
      <origin
        xyz="0 0 0"
        rpy="0 0 0" />
      <geometry>
        <mesh
          filename="package://birdbot02/meshes/base_link.STL" />
      </geometry>
    </collision>
  </link>
  <link
    name="left_pelvis_link">
    <inertial>
      <origin
        xyz="0.0195191764631227 0.0289461148746112 0.0305695366979064"
        rpy="0 0 0" />
      <mass
        value="0.0240397112268165" />
      <inertia
        ixx="1.1307786237561E-05"
        ixy="-1.80216633910009E-08"
        ixz="-7.71530518599285E-09"
        iyy="7.82612339831681E-06"
        iyz="-4.01839288389932E-06"
        izz="7.56186010443175E-06" />
    </inertial>
    <visual>
      <origin
        xyz="0 0 0"
        rpy="0 0 0" />
      <geometry>
        <mesh
          filename="package://birdbot02/meshes/left_pelvis_link.STL" />
      </geometry>
      <material
        name="">
        <color
          rgba="0.792156862745098 0.819607843137255 0.933333333333333 1" />
      </material>
    </visual>
    <collision>
      <origin
        xyz="0 0 0"
        rpy="0 0 0" />
      <geometry>
        <mesh
          filename="package://birdbot02/meshes/left_pelvis_link.STL" />
      </geometry>
    </collision>
  </link>
  <joint
    name="left_pelvis_joint"
    type="continuous">
    <origin
      xyz="0 0 0"
      rpy="0 0 0" />
    <parent
      link="base_link" />
    <child
      link="left_pelvis_link" />
    <axis
      xyz="1 0 0" />
  </joint>
  <link
    name="left_femur_link">
    <inertial>
      <origin
        xyz="-0.072098977190125 -0.000865147877530614 -0.011489683262488"
        rpy="0 0 0" />
      <mass
        value="0.0327221036673699" />
      <inertia
        ixx="3.08407027433505E-06"
        ixy="1.0743452180551E-07"
        ixz="-1.09478352897489E-07"
        iyy="4.60974985312771E-05"
        iyz="-1.75636778798505E-10"
        izz="4.70309283121241E-05" />
    </inertial>
    <visual>
      <origin
        xyz="0 0 0"
        rpy="0 0 0" />
      <geometry>
        <mesh
          filename="package://birdbot02/meshes/left_femur_link.STL" />
      </geometry>
      <material
        name="">
        <color
          rgba="0.792156862745098 0.819607843137255 0.933333333333333 1" />
      </material>
    </visual>
    <collision>
      <origin
        xyz="0 0 0"
        rpy="0 0 0" />
      <geometry>
        <mesh
          filename="package://birdbot02/meshes/left_femur_link.STL" />
      </geometry>
    </collision>
  </link>
  <joint
    name="left_femur_joint"
    type="continuous">
    <origin
      xyz="0.0089 0.060015 0.060193"
      rpy="-1.5708 0.99381 1.5708" />
    <parent
      link="left_pelvis_link" />
    <child
      link="left_femur_link" />
    <axis
      xyz="0 0 1" />
  </joint>
  <link
    name="left_tibia_link">
    <inertial>
      <origin
        xyz="0.0107263196821343 0.0358952134112481 0.0113010537493564"
        rpy="0 0 0" />
      <mass
        value="0.0179012768820449" />
      <inertia
        ixx="2.53318352523956E-05"
        ixy="-3.38090445303627E-09"
        ixz="4.79160355068274E-10"
        iyy="3.80667001141451E-06"
        iyz="-5.71563275601288E-06"
        izz="2.52861842896206E-05" />
    </inertial>
    <visual>
      <origin
        xyz="0 0 0"
        rpy="0 0 0" />
      <geometry>
        <mesh
          filename="package://birdbot02/meshes/left_tibia_link.STL" />
      </geometry>
      <material
        name="">
        <color
          rgba="0.792156862745098 0.819607843137255 0.933333333333333 1" />
      </material>
    </visual>
    <collision>
      <origin
        xyz="0 0 0"
        rpy="0 0 0" />
      <geometry>
        <mesh
          filename="package://birdbot02/meshes/left_tibia_link.STL" />
      </geometry>
    </collision>
  </link>
  <joint
    name="left_tibia_joint"
    type="continuous">
    <origin
      xyz="-0.109999587813109 -0.000301132771852786 0"
      rpy="2.81728180804733 1.5707963267949 0" />
    <parent
      link="left_femur_link" />
    <child
      link="left_tibia_link" />
    <axis
      xyz="1 0 0" />
  </joint>
  <link
    name="left_foot_link">
    <inertial>
      <origin
        xyz="0.0170509883881727 0.0125530979849517 0.0119171387220997"
        rpy="0 0 0" />
      <mass
        value="0.0101123789316251" />
      <inertia
        ixx="7.0777092571663E-07"
        ixy="-6.06986299528361E-08"
        ixz="8.57923294938715E-09"
        iyy="1.10398358440379E-06"
        iyz="-5.43349835219455E-09"
        izz="8.93271102587337E-07" />
    </inertial>
    <visual>
      <origin
        xyz="0 0 0"
        rpy="0 0 0" />
      <geometry>
        <mesh
          filename="package://birdbot02/meshes/left_foot_link.STL" />
      </geometry>
      <material
        name="">
        <color
          rgba="0.792156862745098 0.819607843137255 0.933333333333333 1" />
      </material>
    </visual>
    <collision>
      <origin
        xyz="0 0 0"
        rpy="0 0 0" />
      <geometry>
        <mesh
          filename="package://birdbot02/meshes/left_foot_link.STL" />
      </geometry>
    </collision>
  </link>
  <joint
    name="left_foot_joint"
    type="continuous">
    <origin
      xyz="0 0.100866466861581 0.0291711477810119"
      rpy="1.5707963267949 -0.440155024926565 1.5707963267949" />
    <parent
      link="left_tibia_link" />
    <child
      link="left_foot_link" />
    <axis
      xyz="0 0 1" />
  </joint>
  <link
    name="right_pelvis_link">
    <inertial>
      <origin
        xyz="0.0195191769710061 -0.00108555014338612 0.0420855781859745"
        rpy="0 0 0" />
      <mass
        value="0.0240397140209447" />
      <inertia
        ixx="1.13077877584682E-05"
        ixy="-7.31452960553665E-09"
        ixz="-1.81889058630651E-08"
        iyy="1.1712759568267E-05"
        iyz="1.20217662417577E-07"
        izz="3.6752253344446E-06" />
    </inertial>
    <visual>
      <origin
        xyz="0 0 0"
        rpy="0 0 0" />
      <geometry>
        <mesh
          filename="package://birdbot02/meshes/right_pelvis_link.STL" />
      </geometry>
      <material
        name="">
        <color
          rgba="0.792156862745098 0.819607843137255 0.933333333333333 1" />
      </material>
    </visual>
    <collision>
      <origin
        xyz="0 0 0"
        rpy="0 0 0" />
      <geometry>
        <mesh
          filename="package://birdbot02/meshes/right_pelvis_link.STL" />
      </geometry>
    </collision>
  </link>
  <joint
    name="right_pelvis_joint"
    type="continuous">
    <origin
      xyz="-0.09005 0 0"
      rpy="-0.68587 0 0" />
    <parent
      link="base_link" />
    <child
      link="right_pelvis_link" />
    <axis
      xyz="1 0 0" />
  </joint>
  <link
    name="right_femur_link">
    <inertial>
      <origin
        xyz="-0.0720989772984151 -0.000865147882031 -0.0114896832986954"
        rpy="0 0 0" />
      <mass
        value="0.0327221038203488" />
      <inertia
        ixx="3.08407028364753E-06"
        ixy="1.07434556072849E-07"
        ixz="-1.09478381570175E-07"
        iyy="4.60974989314495E-05"
        iyz="-1.75631503428539E-10"
        izz="4.70309287195409E-05" />
    </inertial>
    <visual>
      <origin
        xyz="0 0 0"
        rpy="0 0 0" />
      <geometry>
        <mesh
          filename="package://birdbot02/meshes/right_femur_link.STL" />
      </geometry>
      <material
        name="">
        <color
          rgba="0.792156862745098 0.819607843137255 0.933333333333333 1" />
      </material>
    </visual>
    <collision>
      <origin
        xyz="0 0 0"
        rpy="0 0 0" />
      <geometry>
        <mesh
          filename="package://birdbot02/meshes/right_femur_link.STL" />
      </geometry>
    </collision>
  </link>
  <joint
    name="right_femur_joint"
    type="continuous">
    <origin
      xyz="0.00890000106220046 0 0.0849999998887829"
      rpy="-1.57079631322609 0.400232188971072 1.57079633208174" />
    <parent
      link="right_pelvis_link" />
    <child
      link="right_femur_link" />
    <axis
      xyz="0 0 1" />
  </joint>
  <link
    name="right_tibia_link">
    <inertial>
      <origin
        xyz="0.0107263105061778 0.0376078092304638 -0.00135395193622948"
        rpy="0 0 0" />
      <mass
        value="0.0179012618672597" />
      <inertia
        ixx="2.53318343365874E-05"
        ixy="-3.02606109065653E-09"
        ixz="1.58284015178503E-09"
        iyy="2.60615885614247E-06"
        iyz="2.33256651546813E-06"
        izz="2.64866923579179E-05" />
    </inertial>
    <visual>
      <origin
        xyz="0 0 0"
        rpy="0 0 0" />
      <geometry>
        <mesh
          filename="package://birdbot02/meshes/right_tibia_link.STL" />
      </geometry>
      <material
        name="">
        <color
          rgba="0.792156862745098 0.819607843137255 0.933333333333333 1" />
      </material>
    </visual>
    <collision>
      <origin
        xyz="0 0 0"
        rpy="0 0 0" />
      <geometry>
        <mesh
          filename="package://birdbot02/meshes/right_tibia_link.STL" />
      </geometry>
    </collision>
  </link>
  <joint
    name="right_tibia_joint"
    type="continuous">
    <origin
      xyz="-0.109999587813113 -0.000301132771853549 0"
      rpy="3.08007868676137 1.5707963267949 0" />
    <parent
      link="right_femur_link" />
    <child
      link="right_tibia_link" />
    <axis
      xyz="1 0 0" />
  </joint>
  <link
    name="right_foot_link">
    <inertial>
      <origin
        xyz="0.0170509869448018 0.0125530976755061 0.0119171386625861"
        rpy="0 0 0" />
      <mass
        value="0.0101123792002471" />
      <inertia
        ixx="7.07770908514634E-07"
        ixy="-6.0698616504654E-08"
        ixz="8.57925221018566E-09"
        iyy="1.10398352835919E-06"
        iyz="-5.43348137253178E-09"
        izz="8.9327107962106E-07" />
    </inertial>
    <visual>
      <origin
        xyz="0 0 0"
        rpy="0 0 0" />
      <geometry>
        <mesh
          filename="package://birdbot02/meshes/right_foot_link.STL" />
      </geometry>
      <material
        name="">
        <color
          rgba="0.792156862745098 0.819607843137255 0.933333333333333 1" />
      </material>
    </visual>
    <collision>
      <origin
        xyz="0 0 0"
        rpy="0 0 0" />
      <geometry>
        <mesh
          filename="package://birdbot02/meshes/right_foot_link.STL" />
      </geometry>
    </collision>
  </link>
  <joint
    name="right_foot_joint"
    type="continuous">
    <origin
      xyz="0 0.104814366264432 -0.006240883317733"
      rpy="1.5707963267949 -0.576383720976984 1.5707963267949" />
    <parent
      link="right_tibia_link" />
    <child
      link="right_foot_link" />
    <axis
      xyz="0 0 1" />
  </joint>
</robot>