<?xml version="1.0" encoding="utf-8"?>
<!-- This URDF was automatically created by SolidWorks to URDF Exporter! Originally created by Stephen Brawner (brawner@gmail.com) 
     Commit Version: 1.6.0-4-g7f85cfe  Build Version: 1.6.7995.38578
     For more information, please see http://wiki.ros.org/sw_urdf_exporter -->
<robot
  name="birdbot01">
  <link
    name="base_link">
    <inertial>
      <origin
        xyz="0 0 0"
        rpy="0 0 0" />
      <mass
        value="0.24692" />
      <inertia
        ixx="0.00022169"
        ixy="-0.00024993"
        ixz="-1.2954E-07"
        iyy="0.00062849"
        iyz="7.1402E-08"
        izz="0.00076587" />
    </inertial>
    <visual>
      <origin
        xyz="0 0 0"
        rpy="0 0 0" />
      <geometry>
        <mesh
          filename="package://birdbot01/meshes/base_link.STL" />
      </geometry>
      <material
        name="">
        <color
          rgba="0.79216 0.81961 0.93333 1" />
      </material>
    </visual>
    <collision>
      <origin
        xyz="0 0 0"
        rpy="0 0 0" />
      <geometry>
        <mesh
          filename="package://birdbot01/meshes/base_link.STL" />
      </geometry>
    </collision>
  </link>
  <link
    name="left_pelvis_link">
    <inertial>
      <origin
        xyz="0.019519 0.028946 0.03057"
        rpy="0 0 0" />
      <mass
        value="0.02404" />
      <inertia
        ixx="1.1308E-05"
        ixy="-1.8022E-08"
        ixz="-7.7153E-09"
        iyy="7.8261E-06"
        iyz="-4.0184E-06"
        izz="7.5619E-06" />
    </inertial>
    <visual>
      <origin
        xyz="0 0 0"
        rpy="0 0 0" />
      <geometry>
        <mesh
          filename="package://birdbot01/meshes/left_pelvis_link.STL" />
      </geometry>
      <material
        name="">
        <color
          rgba="0.79216 0.81961 0.93333 1" />
      </material>
    </visual>
    <collision>
      <origin
        xyz="0 0 0"
        rpy="0 0 0" />
      <geometry>
        <mesh
          filename="package://birdbot01/meshes/left_pelvis_link.STL" />
      </geometry>
    </collision>
  </link>
  <joint
    name="left_pelvis_joint"
    type="continuous">
    <origin
      xyz="0.10303 -0.15325 0.16726"
      rpy="-2.7496 0 -1.5708" />
    <parent
      link="base_link" />
    <child
      link="left_pelvis_link" />
    <axis
      xyz="1 0 0" />
  </joint>
  <link
    name="left_femur_link">
    <inertial>
      <origin
        xyz="-0.072098977190125 -0.000865147877530642 -0.011489683262488"
        rpy="0 0 0" />
      <mass
        value="0.0327221036673699" />
      <inertia
        ixx="3.08407027433505E-06"
        ixy="1.07434521805518E-07"
        ixz="-1.09478352897488E-07"
        iyy="4.60974985312771E-05"
        iyz="-1.75636778798876E-10"
        izz="4.70309283121241E-05" />
    </inertial>
    <visual>
      <origin
        xyz="0 0 0"
        rpy="0 0 0" />
      <geometry>
        <mesh
          filename="package://birdbot01/meshes/left_femur_link.STL" />
      </geometry>
      <material
        name="">
        <color
          rgba="0.792156862745098 0.819607843137255 0.933333333333333 1" />
      </material>
    </visual>
    <collision>
      <origin
        xyz="0 0 0"
        rpy="0 0 0" />
      <geometry>
        <mesh
          filename="package://birdbot01/meshes/left_femur_link.STL" />
      </geometry>
    </collision>
  </link>
  <joint
    name="left_femur_joint"
    type="continuous">
    <origin
      xyz="0.0089 0.060015 0.060193"
      rpy="-1.5708 0.99381 1.5708" />
    <parent
      link="left_pelvis_link" />
    <child
      link="left_femur_link" />
    <axis
      xyz="0 0 1" />
  </joint>
  <link
    name="left_tibia_link">
    <inertial>
      <origin
        xyz="0.010726 0.035895 0.011301"
        rpy="0 0 0" />
      <mass
        value="0.017901" />
      <inertia
        ixx="2.5332E-05"
        ixy="-3.3809E-09"
        ixz="4.7916E-10"
        iyy="3.8067E-06"
        iyz="-5.7156E-06"
        izz="2.5286E-05" />
    </inertial>
    <visual>
      <origin
        xyz="0 0 0"
        rpy="0 0 0" />
      <geometry>
        <mesh
          filename="package://birdbot01/meshes/left_tibia_link.STL" />
      </geometry>
      <material
        name="">
        <color
          rgba="0.79216 0.81961 0.93333 1" />
      </material>
    </visual>
    <collision>
      <origin
        xyz="0 0 0"
        rpy="0 0 0" />
      <geometry>
        <mesh
          filename="package://birdbot01/meshes/left_tibia_link.STL" />
      </geometry>
    </collision>
  </link>
  <joint
    name="left_tibia_joint"
    type="continuous">
    <origin
      xyz="-0.11 -0.00030113 0"
      rpy="2.8173 1.5708 0" />
    <parent
      link="left_femur_link" />
    <child
      link="left_tibia_link" />
    <axis
      xyz="1 0 0" />
  </joint>
  <link
    name="left_foot_link">
    <inertial>
      <origin
        xyz="0.0170509883881726 0.0125530979849517 0.0119171387220997"
        rpy="0 0 0" />
      <mass
        value="0.0101123789316251" />
      <inertia
        ixx="7.0777092571663E-07"
        ixy="-6.06986299528361E-08"
        ixz="8.57923294938712E-09"
        iyy="1.10398358440379E-06"
        iyz="-5.43349835219453E-09"
        izz="8.93271102587337E-07" />
    </inertial>
    <visual>
      <origin
        xyz="0 0 0"
        rpy="0 0 0" />
      <geometry>
        <mesh
          filename="package://birdbot01/meshes/left_foot_link.STL" />
      </geometry>
      <material
        name="">
        <color
          rgba="0.792156862745098 0.819607843137255 0.933333333333333 1" />
      </material>
    </visual>
    <collision>
      <origin
        xyz="0 0 0"
        rpy="0 0 0" />
      <geometry>
        <mesh
          filename="package://birdbot01/meshes/left_foot_link.STL" />
      </geometry>
    </collision>
  </link>
  <joint
    name="left_foot_joint"
    type="continuous">
    <origin
      xyz="0 0.100866466861581 0.0291711477810119"
      rpy="1.5707963267949 -0.440155024926565 1.5707963267949" />
    <parent
      link="left_tibia_link" />
    <child
      link="left_foot_link" />
    <axis
      xyz="0 0 1" />
  </joint>
  <link
    name="right_pelvis_link">
    <inertial>
      <origin
        xyz="0.0195191769710061 -0.00108555014338613 0.0420855781859746"
        rpy="0 0 0" />
      <mass
        value="0.0240397140209447" />
      <inertia
        ixx="1.13077877584682E-05"
        ixy="-7.31452960553708E-09"
        ixz="-1.8188905863066E-08"
        iyy="1.1712759568267E-05"
        iyz="1.20217662417579E-07"
        izz="3.67522533444459E-06" />
    </inertial>
    <visual>
      <origin
        xyz="0 0 0"
        rpy="0 0 0" />
      <geometry>
        <mesh
          filename="package://birdbot01/meshes/right_pelvis_link.STL" />
      </geometry>
      <material
        name="">
        <color
          rgba="0.792156862745098 0.819607843137255 0.933333333333333 1" />
      </material>
    </visual>
    <collision>
      <origin
        xyz="0 0 0"
        rpy="0 0 0" />
      <geometry>
        <mesh
          filename="package://birdbot01/meshes/right_pelvis_link.STL" />
      </geometry>
    </collision>
  </link>
  <joint
    name="right_pelvis_joint"
    type="continuous">
    <origin
      xyz="0.10303 -0.063199 0.16726"
      rpy="2.8477 0 -1.5708" />
    <parent
      link="base_link" />
    <child
      link="right_pelvis_link" />
    <axis
      xyz="1 0 0" />
  </joint>
  <link
    name="right_femur_link">
    <inertial>
      <origin
        xyz="-0.0720989772984125 -0.000865147882030196 -0.0114896832986955"
        rpy="0 0 0" />
      <mass
        value="0.0327221038203488" />
      <inertia
        ixx="3.08407028364754E-06"
        ixy="1.07434556072852E-07"
        ixz="-1.09478381570171E-07"
        iyy="4.60974989314495E-05"
        iyz="-1.75631503429254E-10"
        izz="4.70309287195409E-05" />
    </inertial>
    <visual>
      <origin
        xyz="0 0 0"
        rpy="0 0 0" />
      <geometry>
        <mesh
          filename="package://birdbot01/meshes/right_femur_link.STL" />
      </geometry>
      <material
        name="">
        <color
          rgba="0.792156862745098 0.819607843137255 0.933333333333333 1" />
      </material>
    </visual>
    <collision>
      <origin
        xyz="0 0 0"
        rpy="0 0 0" />
      <geometry>
        <mesh
          filename="package://birdbot01/meshes/right_femur_link.STL" />
      </geometry>
    </collision>
  </link>
  <joint
    name="right_femur_joint"
    type="continuous">
    <origin
      xyz="0.0089 0 0.085"
      rpy="-1.5708 0.40023 1.5708" />
    <parent
      link="right_pelvis_link" />
    <child
      link="right_femur_link" />
    <axis
      xyz="0 0 1" />
  </joint>
  <link
    name="right_tibia_link">
    <inertial>
      <origin
        xyz="0.0107263105061778 0.0376078092304638 -0.00135395193622945"
        rpy="0 0 0" />
      <mass
        value="0.0179012618672597" />
      <inertia
        ixx="2.53318343365874E-05"
        ixy="-3.02606109065682E-09"
        ixz="1.58284015178415E-09"
        iyy="2.60615885614249E-06"
        iyz="2.33256651546813E-06"
        izz="2.64866923579179E-05" />
    </inertial>
    <visual>
      <origin
        xyz="0 0 0"
        rpy="0 0 0" />
      <geometry>
        <mesh
          filename="package://birdbot01/meshes/right_tibia_link.STL" />
      </geometry>
      <material
        name="">
        <color
          rgba="0.792156862745098 0.819607843137255 0.933333333333333 1" />
      </material>
    </visual>
    <collision>
      <origin
        xyz="0 0 0"
        rpy="0 0 0" />
      <geometry>
        <mesh
          filename="package://birdbot01/meshes/right_tibia_link.STL" />
      </geometry>
    </collision>
  </link>
  <joint
    name="right_tibia_joint"
    type="continuous">
    <origin
      xyz="-0.11 -0.00030113 0"
      rpy="3.0801 1.5708 0" />
    <parent
      link="right_femur_link" />
    <child
      link="right_tibia_link" />
    <axis
      xyz="1 0 0" />
  </joint>
  <link
    name="right_foot_link">
    <inertial>
      <origin
        xyz="0.0170509881311838 0.0125530979235213 0.0119171382596389"
        rpy="0 0 0" />
      <mass
        value="0.0101123781948647" />
      <inertia
        ixx="7.07770882181402E-07"
        ixy="-6.06986177172493E-08"
        ixz="8.57924463660672E-09"
        iyy="1.10398350219478E-06"
        iyz="-5.43347553573532E-09"
        izz="8.93271073437318E-07" />
    </inertial>
    <visual>
      <origin
        xyz="0 0 0"
        rpy="0 0 0" />
      <geometry>
        <mesh
          filename="package://birdbot01/meshes/right_foot_link.STL" />
      </geometry>
      <material
        name="">
        <color
          rgba="0.792156862745098 0.819607843137255 0.933333333333333 1" />
      </material>
    </visual>
    <collision>
      <origin
        xyz="0 0 0"
        rpy="0 0 0" />
      <geometry>
        <mesh
          filename="package://birdbot01/meshes/right_foot_link.STL" />
      </geometry>
    </collision>
  </link>
  <joint
    name="right_foot_joint"
    type="continuous">
    <origin
      xyz="0 0.10481 -0.0062409"
      rpy="1.5708 -0.57638 1.5708" />
    <parent
      link="right_tibia_link" />
    <child
      link="right_foot_link" />
    <axis
      xyz="0 0 1" />
  </joint>
</robot>